<?xml version="1.0"?>
<robot name="common" xmlns:xacro="http://www.ros.org/wiki/xacro">

  <!-- PROPERTY LIST -->
  <!-- All units in m-kg-s-radians unit system -->
  <xacro:property name="M_PI" value="3.1415926535897931" />

  <!-- Inertial macros. Units are kg*m^2 -->
  <xacro:macro name="box_inertia" params="m x y z">
    <inertia ixx="${m*(y*y+z*z)/12}" ixy = "0" ixz = "0"
             iyy="${m*(z*z+x*x)/12}" iyz = "0"
             izz="${m*(x*x+y*y)/12}" /> 
  </xacro:macro>
  <xacro:macro name="cylinder_inertia" params="m r h">
    <inertia ixx="${m*(3*r*r+h*h)/12}" ixy="0" ixz="0"
             iyy="${m*(3*r*r+h*h)/12}" iyz="0"
             izz="${m*r*r/2}" />
  </xacro:macro>
  <xacro:macro name="sphere_inertia" params="m r">
    <inertia ixx="${m*r*r/5}" ixy="0" ixz="0"
             iyy="${m*r*r/5}" iyz="0"
             izz="${m*r*r/5}" /> 
  </xacro:macro>
  
  <xacro:macro name="gazebo_transmission" params="p">
    <transmission name="${p}_trans" type="SimpleTransmission">
      <type>transmission_interface/SimpleTransmission</type>
      <actuator name="${p}_motor">
        <mechanicalReduction>30</mechanicalReduction>
      </actuator>
      <joint name="${p}_joint">
        <hardwareInterface>hardware_interface/VelocityJointInterface</hardwareInterface>
      </joint>
    </transmission>
  </xacro:macro>
  
  <!-- Default wheel joint-->>
  <xacro:macro name="wheel_macro" params="parent prefix xyz color">
    <joint name="${prefix}_joint" type="continuous">
      <parent link="${parent}"/>
      <child link="${prefix}_link"/>
      <origin xyz="${xyz}" rpy="0 0 0"/>
      <axis xyz="0 -1 0"/>
    </joint>
    <xacro:gazebo_transmission p="${prefix}"/>
    <link name="${prefix}_link">
    <visual>
      <origin xyz="0 0 0" rpy="0 0 1.57079632679"/>
      <geometry>
	      <mesh filename="package://jetbot_description/meshes/DAE/JetBot-v3-Wheel222.dae"/>
      </geometry>
      <material name="${color}"/>
    </visual>

    <collision>
      <origin xyz="0 0 0" rpy="0 0 1.57079632679"/>
      <geometry>
	      <mesh filename="package://jetbot_description/meshes/DAE/JetBot-v3-Wheel222.dae"/>
      </geometry>
    </collision>

      <inertial>
        <origin xyz="0 0 0" rpy="0 1.5707 1.5707"/>
        <mass value="${wheel_mass}" />
        <xacro:cylinder_inertia  m="${wheel_mass}"
          r="${wheel_radius}" h="${wheel_width}" />
      </inertial>
    </link>
    <gazebo reference="${prefix}_link">
      <mu1>0.2</mu1>
      <mu2>0.2</mu2>
      <kp value="50000" />
      <kd value="10" />
      <material>Gazebo/white</material>
    </gazebo>
  </xacro:macro>

  <material name="black">
    <color rgba="0.0 0.0 0.0 1.0"/>
  </material>

  <material name="blue">
    <color rgba="0.0 0.0 0.8 1.0"/>
  </material>

  <material name="green">
    <color rgba="0.0 0.8 0.0 1.0"/>
  </material>

  <material name="grey">
    <color rgba="0.2 0.2 0.2 1.0"/>
  </material>

  <material name="orange">
    <color rgba="${255/255} ${108/255} ${10/255} 1.0"/>
  </material>

  <material name="brown">
    <color rgba="${222/255} ${207/255} ${195/255} 1.0"/>
  </material>

  <material name="red">
    <color rgba="0.8 0.0 0.0 1.0"/>
  </material>

  <material name="white">
    <color rgba="1.0 1.0 1.0 1.0"/>
  </material>

</robot>
